<?xml version="1.0"?>

<!--
Use the following command to check your xacro file:
check_urdf src/my_robot/urdf/my_robot.xacro

All inks are centered to the origin. Their relative positions are then set by
the joints definitions.

In order to specify material colors, visual tag names must start with the link
name. E.g. <visual name="left_wheel_visual"> for the link "left_wheel".
-->

<robot name="my_robot" xmlns:xacro="http://www.ros.org/wiki/xacro">

    <xacro:include filename="$(find my_robot)/urdf/my_robot.gazebo" />

    <link name="robot_footprint"></link>

    <joint name="robot_footprint_joint" type="fixed">
        <origin xyz="0 0 0" rpy="0 0 0" />
        <parent link="robot_footprint"/>
        <child link="chassis" />
    </joint>

    <joint type="continuous" name="left_wheel_hinge">
        <origin xyz="0 0.13 0" rpy="0 0 0"/>
        <parent link="chassis"/>
        <child link="left_wheel"/>
        <axis xyz="0 1 0" rpy="0 0 0"/>
        <limit effort="10000" velocity="1000"/>
        <dynamics damping="1.0" friction="1.0"/>
    </joint>

    <joint type="continuous" name="right_wheel_hinge">
        <origin xyz="0 -0.13 0" rpy="0 0 0"/>
        <parent link="chassis"/>
        <child link="right_wheel"/>
        <axis xyz="0 1 0" rpy="0 0 0"/>
        <limit effort="10000" velocity="1000"/>
        <dynamics damping="1.0" friction="1.0"/>
    </joint>

    <!-- RGB camera -->
    <joint type="fixed" name="camera_joint">
        <origin xyz="0.2 0 0" rpy="0 0 0"/>
        <parent link="chassis"/>
        <child link="camera"/>
        <axis xyz="0 1 0" rpy="0 0 0"/>
    </joint>

    <!-- RGBD camera -->
    <joint type="fixed" name="camera_optical_joint">
        <origin xyz="0 0 0" rpy="-1.5707 0 -1.5707"/>
        <parent link="camera"/>
        <child link="camera_link_optical"/>
    </joint>

    <joint type="fixed" name="hokuyo_joint">
        <origin xyz="0.15 0 0.1" rpy="0 0 0"/>
        <parent link="chassis"/>
        <child link="hokuyo"/>
        <axis xyz="0 1 0" rpy="0 0 0"/>
    </joint>

    <link name="chassis">
        <pose>0 0 0.1 0 0 0</pose>

        <inertial>
            <mass value="15.0"/>
            <origin xyz="0.0 0 0" rpy=" 0 0 0"/>
            <inertia
                ixx="0.1" ixy="0" ixz="0"
                iyy="0.1" iyz="0"
                izz="0.1"
            />
        </inertial>

        <collision name="collision">
            <origin xyz="0 0 0" rpy=" 0 0 0"/>
            <geometry>
                <box size="0.4 0.2 0.1"/>
            </geometry>
        </collision>

        <visual name="chassis_visual">
            <origin xyz="0 0 0" rpy=" 0 0 0"/>
            <geometry>
		<mesh filename="package://my_robot/meshes/chassis.dae"/>
                <!--<box size="0.4 0.2 0.1"/>-->
            </geometry>
        </visual>

        <collision name="back_caster_collision">
            <origin xyz="-0.15 0 -0.05" rpy=" 0 0 0"/>
            <geometry>
                <sphere radius="0.0499"/>
            </geometry>
        </collision>

        <visual name="back_caster_visual">
            <origin xyz="-0.15 0 -0.05" rpy=" 0 0 0"/>
            <geometry>
                <sphere radius="0.05"/>
            </geometry>
        </visual>

        <collision name="front_caster_collision">
            <origin xyz="0.15 0 -0.05" rpy=" 0 0 0"/>
            <geometry>
                <sphere radius="0.0499"/>
            </geometry>
        </collision>

        <visual name="front_caster_visual">
            <origin xyz="0.15 0 -0.05" rpy=" 0 0 0"/>
            <geometry>
                <sphere radius="0.05"/>
            </geometry>
        </visual>

    </link>

    <link name="left_wheel">
        <pose>0 0 0 0 0 0</pose>

        <inertial>
            <mass value="5.0"/>
            <origin xyz="0 0 0" rpy=" 0 0 0"/>
            <inertia
                ixx="0.1" ixy="0" ixz="0"
                iyy="0.1" iyz="0"
                izz="0.1"
            />
        </inertial>

        <collision name="left_wheel_collision">
            <origin xyz="0 0 0" rpy=" 0 1.5707 1.5707"/>
            <geometry>
                <cylinder radius="0.1" length="0.05"/>
            </geometry>
        </collision>

        <visual name="left_wheel_visual">
            <origin xyz="0 0 0" rpy=" 0 1.5707 1.5707"/>
            <geometry>
                <cylinder radius="0.1" length="0.05"/>
            </geometry>
        </visual>

    </link>

    <link name="right_wheel">
        <pose>0 0 0 0 0 0</pose>

        <inertial>
            <mass value="5.0"/>
            <origin xyz="0 0 0" rpy=" 0 0 0"/>
            <inertia
                ixx="0.1" ixy="0" ixz="0"
                iyy="0.1" iyz="0"
                izz="0.1"
            />
        </inertial>

        <collision name="right_wheel_collision">
            <origin xyz="0 0 0" rpy=" 0 1.5707 1.5707"/>
            <geometry>
                <cylinder radius="0.1" length="0.05"/>
            </geometry>
        </collision>

        <visual name="right_wheel_visual">
            <origin xyz="0 0 0" rpy=" 0 1.5707 1.5707"/>
            <geometry>
                <cylinder radius="0.1" length="0.05"/>
            </geometry>
        </visual>

    </link>

    <!-- RGB camera -->
    <link name="camera">
        <pose>0 0 0 0 0 0</pose>

        <inertial>
            <mass value="0.1"/>
            <origin xyz="0.05 0.05 0.05" rpy=" 0 0 0"/>
            <inertia
                ixx="1e-6" ixy="0" ixz="0"
                iyy="1e-6" iyz="0"
                izz="1e-6"
            />
        </inertial>

        <collision name="camera_collision">
            <origin xyz="0 0 0" rpy=" 0 0 0"/>
            <geometry>
                <box size="0.05 0.05 0.05"/>
            </geometry>
        </collision>

        <visual name="camera_visual">
            <origin xyz="0 0 0" rpy=" 0 0 0"/>
            <geometry>
                <box size="0.05 0.05 0.05"/>
            </geometry>
        </visual>
    </link>

    <!-- RGBD camera -->
    <link name="camera_link_optical">
    </link>

    <link name="hokuyo">
        <pose>0 0 0 0 0 0</pose>

        <inertial>
            <mass value="1e-5"/>
            <origin xyz="0.05 0.05 0.05" rpy=" 0 0 0"/>
            <inertia
                ixx="1e-6" ixy="0" ixz="0"
                iyy="1e-6" iyz="0"
                izz="1e-6"
            />
        </inertial>

        <collision name="hokuyo_collision">
            <origin xyz="0 0 0" rpy=" 0 0 0"/>
            <geometry>
                <box size="0.1 0.1 0.1"/>
            </geometry>
        </collision>

        <visual name="hokuyo_visual">
            <origin xyz="0 0 0" rpy=" 0 0 0"/>
            <geometry>
                <mesh filename="package://my_robot/meshes/hokuyo.dae"/>
            </geometry>
        </visual>
    </link>


    <gazebo reference="left_wheel">
        <material>Gazebo/Green</material>
    </gazebo>

    <gazebo reference="right_wheel">
        <material>Gazebo/Green</material>
    </gazebo>

    <gazebo reference="chassis">
        <material>Gazebo/Red</material>
    </gazebo>

    <gazebo reference="camera">
        <material>Gazebo/Yellow</material>
    </gazebo>

</robot>

